Workbook

Sheet 4.1.1
A2: STANDARD 4: PEMBELAJARAN DAN PEMUDAHCARAAN (PdPc)
A4: Nama Guru:
B5: No. KP:
B6: Jenis Penilaian:
B7: Tarikh:
B8: Mata pelajaran:
B9: Kelas:
B11: ARAHAN : | C11: Taipkan skor 1 pada baris SKOR SEKOLAH di mana-mana satu skala penskoran sahaja.
A13: PERNYATAAN STANDARD
A14: Guru berperanan sebagai pemudah cara dalam proses pengajaran dan pembelajaran (PdP) yang berkesan untuk memperkembangkan potensi murid secara menyeluruh dan meningkatkan pencapaian murid pada tahap optimum secara berterusan.
A15: ASPEK 4.1 : GURU SEBAGAI PERANCANG
A16: 4.1.1
A17: KRITERIA KRITIKAL
A18: Guru bertindak sebagai perancang untuk memastikan kesediaan dan persediaan rapi dalam melaksanakan Pembelajaran dan Pemudahcaraan (PdPc).
A19: STANDARD KUALITI
A20: Guru merancang pelaksanaan PdPc secara profesional dan sistematik.
A21: TINDAKAN UNTUK MENCAPAI STANDARD
A22: Menyediakan RPH, menentukan kaedah pentaksiran dan menyediakan sumber pendidikan mengikut keupayaan murid, peruntukan masa dan mematuhi arahan yang berkuat kuasa.
A23: TINDAKAN | D23: PENSKORAN
A24: Guru merancang pelaksanaan PdPc dengan: | D24: 4 | F24: 3 | G24: 2 | H24: 1 | I24: 0
A25: a) | B25: menyediakan RPH yang mengandungi objektif yang boleh diukur dan aktiviti pembelajaran yang sesuai | D25: i. | E25: mengikut pelbagai aras keupayaan murid | F25: dengan mengambil kira perkara (i) dan (ii) atau perkara (i) dan (iii) | G25: dengan mengambil kira perkara (ii) dan (iii) | H25: dengan mengambil kira mana-mana satu (1) perkara | I25: tidak mengambil kira mana-mana perkara | J25: =IF(SUM(F25:I25)>1,"X","")
D26: ii. | E26: mengikut peruntukan masa yang ditetapkan | J26: =IF(SUM(F26:I26)>1,"X","")
D27: iii. | E27: dengan mematuhi arahan yang berkuat kuasa/ketetapan kurikulum | J27: =IF(SUM(F27:I27)>1,"X","")
A28: SKOR SEKOLAH | J28: =IF((D28+F28+G28+H28+I28)>1,"X",IF((D28+F28+G28+H28+I28)=0,0,"")) -> 0
A29: b) | B29: menentukan kaedah pentaksiran | D29: i. | E29: mengikut pelbagai aras keupayaan murid | F29: dengan mengambil kira perkara (i) dan (ii) atau perkara (i) dan (iii) | G29: dengan mengambil kira perkara (ii) dan (iii) | H29: dengan mengambil kira mana-mana satu (1) perkara | I29: tidak mengambil kira mana-mana perkara | J29: =IF(SUM(F29:I29)>1,"X","")
D30: ii. | E30: mengikut peruntukan masa yang ditetapkan | J30: =IF(SUM(F30:I30)>1,"X","")
D31: iii. | E31: dengan mematuhi arahan yang berkuat kuasa/ketetapan kurikulum | J31: =IF(SUM(F31:I31)>1,"X","")
A32: SKOR SEKOLAH | J32: =IF((D32+F32+G32+H32+I32)>1,"X",IF((D32+F32+G32+H32+I32)=0,0,"")) -> 0
A33: c) | B33: menyediakan ABM/BBM/BBB/TMK | D33: i. | E33: mengikut pelbagai aras keupayaan murid | F33: dengan mengambil kira perkara (i) dan (ii) atau perkara (i) dan (iii) | G33: dengan mengambil kira perkara (ii) dan (iii) | H33: dengan mengambil kira mana-mana satu (1) perkara | I33: tidak mengambil kira mana-mana perkara | J33: =IF(SUM(F33:I33)>1,"X","")
D34: ii. | E34: mengikut peruntukan masa yang ditetapkan | J34: =IF(SUM(F34:I34)>1,"X","")
D35: iii. | E35: dengan mematuhi arahan yang berkuat kuasa/ketetapan kurikulum | J35: =IF(SUM(F35:I35)>1,"X","")
A36: SKOR SEKOLAH | J36: =IF((D36+F36+G36+H36+I36)>1,"X",IF((D36+F36+G36+H36+I36)=0,0,"")) -> 0
A37: Jumlah Frekuensi Aspek 4.1.1 | D37: =IF(SUM(D28+D32+D36)="","",(SUM(D28+D32+D36))) -> 0 | F37: =IF(SUM(F28+F32+F36)="","",(SUM(F28+F32+F36))) -> 0 | G37: =IF(SUM(G28+G32+G36)="","",(SUM(G28+G32+G36))) -> 0 | H37: =IF(SUM(H28+H32+H36)="","",(SUM(H28+H32+H36))) -> 0 | I37: =IF(SUM(I28+I32+I36)="","",(SUM(I28+I32+I36))) -> 0
A38: Skor | D38: =IF((D37)="","",(D37)*D24) -> 0 | F38: =IF((F37)="","",(F37)*F24) -> 0 | G38: =IF((G37)="","",(G37)*G24) -> 0 | H38: =IF((H37)="","",(H37)*H24) -> 0 | I38: =IF((I37)="","",(I37)*I24) -> 0
A39: Jumlah Skor Aspek 4.1.1 | D39: =IF(J39="X","X",SUM(D38:I38)) -> 0 | J39: =IF(OR(J36="X",J32="X",J28="X"),"X",1) -> 1

Sheet 4.2.1
B2: ARAHAN : | C2: Taipkan skor 1 pada baris SKOR SEKOLAH di mana-mana satu skala penskoran sahaja.
A4: ASPEK 4.2 : GURU SEBAGAI PENGAWAL
A5: 4.2.1
A6: KRITERIA KRITIKAL
A7: Guru bertindak sebagai pengawal pelaksanaan PdPc untuk memastikan kelancaran proses pembelajaran mengikut perancangan
A8: STANDARD KUALITI
A9: Guru mengawal proses pembelajaran secara profesional dan terancang.
A10: TINDAKAN UNTUK MENCAPAI STANDARD
A11: Mengelola isi pelajaran dan masa serta memberi peluang kepada penyertaan aktif murid dalam PdPc dengan menepati objektif pelajaran, mengikut keupayaan murid dan dari semasa ke semasa.
A12: TINDAKAN | D12: PENSKORAN
A13: Guru mengawal proses pembelajaran dengan: | D13: 4 | F13: 3 | G13: 2 | H13: 1 | I13: 0
A14: a) | B14: mengelola isi pelajaran/skop pembelajaran yang dirancang | D14: i. | E14: dengan menepati objektif pembelajaran | F14: dengan mengambil kira perkara (i) dan (ii) atau perkara (i) dan (iii) | G14: dengan mengambil kira perkara (ii) dan (iii) | H14: dengan mengambil kira mana-mana satu (1) perkara | I14: tidak mengambil kira mana-mana perkara | J14: =IF(SUM(F14:I14)>1,"X","")
D15: ii. | E15: mengikut pelbagai aras keupayaan murid/pembelajaran terbeza | J15: =IF(SUM(F15:I15)>1,"X","")
D16: iii. | E16: dari semasa ke semasa | J16: =IF(SUM(F16:I16)>1,"X","")
A17: SKOR SEKOLAH | J17: =IF((D17+F17+G17+H17+I17)>1,"X",IF((D17+F17+G17+H17+I17)=0,0,"")) -> 0
A18: b) | B18: mengelola masa PdP selaras dengan aktiviti pembelajaran | D18: i. | E18: dengan menepati objektif pembelajaran | F18: dengan mengambil kira perkara (i) dan (ii) atau perkara (i) dan (iii) | G18: dengan mengambil kira perkara (ii) dan (iii) | H18: dengan mengambil kira mana-mana satu (1) perkara | I18: tidak mengambil kira mana-mana perkara | J18: =IF(SUM(F18:I18)>1,"X","")
D19: ii. | E19: mengikut pelbagai aras keupayaan murid/pembelajaran terbeza | J19: =IF(SUM(F19:I19)>1,"X","")
D20: iii. | E20: dari semasa ke semasa | J20: =IF(SUM(F20:I20)>1,"X","")
A21: SKOR SEKOLAH | J21: =IF((D21+F21+G21+H21+I21)>1,"X",IF((D21+F21+G21+H21+I21)=0,0,"")) -> 0
A22: c) | B22: memberi peluang kepada penyertaan aktif murid | D22: i. | E22: dengan menepati objektif pembelajaran | F22: dengan mengambil kira perkara (i) dan (ii) atau perkara (i) dan (iii) | G22: dengan mengambil kira perkara (ii) dan (iii) | H22: dengan mengambil kira mana-mana satu (1) perkara | I22: tidak mengambil kira mana-mana perkara | J22: =IF(SUM(F22:I22)>1,"X","")
D23: ii. | E23: mengikut pelbagai aras keupayaan murid/pembelajaran terbeza | J23: =IF(SUM(F23:I23)>1,"X","")
D24: iii. | E24: dari semasa ke semasa | J24: =IF(SUM(F24:I24)>1,"X","")
A25: SKOR SEKOLAH | J25: =IF((D25+F25+G25+H25+I25)>1,"X",IF((D25+F25+G25+H25+I25)=0,0,"")) -> 0
A26: Jumlah Frekuensi Aspek 4.2.1 | D26: =IF(SUM(D17+D21+D25)="","",(SUM(D17+D21+D25))) -> 0 | F26: =IF(SUM(F17+F21+F25)="","",(SUM(F17+F21+F25))) -> 0 | G26: =IF(SUM(G17+G21+G25)="","",(SUM(G17+G21+G25))) -> 0 | H26: =IF(SUM(H17+H21+H25)="","",(SUM(H17+H21+H25))) -> 0 | I26: =IF(SUM(I17+I21+I25)="","",(SUM(I17+I21+I25))) -> 0
A27: Skor | D27: =IF((D26)="","",(D26)*D13) -> 0 | F27: =IF((F26)="","",(F26)*F13) -> 0 | G27: =IF((G26)="","",(G26)*G13) -> 0 | H27: =IF((H26)="","",(H26)*H13) -> 0 | I27: =IF((I26)="","",(I26)*I13) -> 0
A28: Jumlah Skor Aspek 4.2.1 | D28: =IF(J28="X","X",SUM(D27:I27)) -> 0 | J28: =IF(OR(J25="X",J21="X",J17="X"),"X",1) -> 1

Sheet 4.2.2
B2: ARAHAN : | C2: Taipkan skor 1 pada baris SKOR SEKOLAH di mana-mana satu skala penskoran sahaja.
A4: ASPEK 4.2 : GURU SEBAGAI PENGAWAL
A5: 4.2.2
A6: KRITERIA KRITIKAL
A7: Guru bertindak sebagai pengawal pelaksanaan PdPc untuk memastikan kelancaran proses pembelajaran mengikut perancangan.
A8: STANDARD KUALITI
A9: Guru mengawal suasana pembelajaran secara profesional dan terancang.
A10: TINDAKAN UNTUK MENCAPAI STANDARD
A11: Mengawasi komunikasi dan perlakuan murid, menyusun atur kedudukan murid dan mewujudkan suasana pembelajaran yang menyeronokkan mengikut kesesuaian dan keperluan, secara berhemah, menyeluruh dan dari semasa ke semasa.
A12: TINDAKAN | D12: PENSKORAN
A13: Guru mengawal suasana pembelajaran dengan: | D13: 4 | F13: 3 | G13: 2 | H13: 1 | I13: 0
A14: a) | B14: mengawasi komunikasi murid dalam PdPc | D14: i. | E14: secara berhemah/mengikut kesesuaian | F14: dengan mengambil kira perkara (i) dan (ii) atau perkara (i) dan (iii) | G14: dengan mengambil kira perkara (ii) dan (iii) | H14: dengan mengambil kira mana-mana satu (1) perkara | I14: tidak mengambil kira mana-mana perkara
D15: ii. | E15: secara menyeluruh meliputi semua murid
D16: iii. | E16: dari semasa ke semasa
A17: SKOR SEKOLAH | F17: 1 | J17: =IF((D17+F17+G17+H17+I17)>1,"X",IF((D17+F17+G17+H17+I17)=0,0,""))
A18: b) | B18: mengawasi perlakuan murid dalam PdPc | D18: i. | E18: secara berhemah/mengikut kesesuaian | F18: dengan mengambil kira perkara (i) dan (ii) atau perkara (i) dan (iii) | G18: dengan mengambil kira perkara (ii) dan (iii) | H18: dengan mengambil kira mana-mana satu (1) perkara | I18: tidak mengambil kira mana-mana perkara
D19: ii. | E19: secara menyeluruh meliputi semua murid
D20: iii. | E20: dari semasa ke semasa
A21: SKOR SEKOLAH | F21: 1 | J21: =IF((D21+F21+G21+H21+I21)>1,"X",IF((D21+F21+G21+H21+I21)=0,0,""))
A22: c) | B22: menyusun atur kedudukan murid | D22: i. | E22: secara berhemah/mengikut kesesuaian | F22: dengan mengambil kira perkara (i) dan (ii) atau perkara (i) dan (iii) | G22: dengan mengambil kira perkara (ii) dan (iii) | H22: dengan mengambil kira mana-mana satu (1) perkara | I22: tidak mengambil kira mana-mana perkara
D23: ii. | E23: secara menyeluruh meliputi semua murid
D24: iii. | E24: dari semasa ke semasa
A25: SKOR SEKOLAH | D25: 1 | J25: =IF((D25+F25+G25+H25+I25)>1,"X",IF((D25+F25+G25+H25+I25)=0,0,""))
A26: d) | B26: melaksanakan aktiviti pembelajaran yang menyeronokkan | D26: i. | E26: secara berhemah/mengikut kesesuaian | F26: dengan mengambil kira perkara (i) dan (ii) atau perkara (i) dan (iii) | G26: dengan mengambil kira perkara (ii) dan (iii) | H26: dengan mengambil kira mana-mana satu (1) perkara | I26: tidak mengambil kira mana-mana perkara
D27: ii. | E27: secara menyeluruh meliputi semua murid
D28: iii. | E28: dari semasa ke semasa
A29: SKOR SEKOLAH | D29: 1 | J29: =IF((D29+F29+G29+H29+I29)>1,"X",IF((D29+F29+G29+H29+I29)=0,0,""))
A30: Jumlah Frekuensi Aspek 4.2.2 | D30: =IF(SUM(D17+D21+D25+D29)="","",(SUM(D17+D21+D25+D29))) -> 2 | F30: =IF(SUM(F17+F21+F25+F29)="","",(SUM(F17+F21+F25+F29))) -> 2 | G30: =IF(SUM(G17+G21+G25+G29)="","",(SUM(G17+G21+G25+G29))) -> 0 | H30: =IF(SUM(H17+H21+H25+H29)="","",(SUM(H17+H21+H25+H29))) -> 0 | I30: =IF(SUM(I17+I21+I25+I29)="","",(SUM(I17+I21+I25+I29))) -> 0
A31: Skor | D31: =IF((D30)="","",(D30)*D13) -> 8 | F31: =IF((F30)="","",(F30)*F13) -> 6 | G31: =IF((G30)="","",(G30)*G13) -> 0 | H31: =IF((H30)="","",(H30)*H13) -> 0 | I31: =IF((I30)="","",(I30)*I13) -> 0
A32: Jumlah Skor Aspek 4.2.2 | D32: =IF(J32="X","X",SUM(D31:I31)) -> 14 | J32: =IF(OR(J29="X",J25="X",J21="X",J17="X"),"X",1) -> 1

Sheet 4.3.1
B2: ARAHAN : | C2: Taipkan skor 1 pada baris SKOR SEKOLAH di mana-mana satu skala penskoran sahaja.
A4: ASPEK 4.3 : GURU SEBAGAI PEMBIMBING
A5: 4.3.1
A6: KRITERIA KRITIKAL
A7: Guru bertindak sebagai pembimbing untuk membolehkan murid menguasai pengetahuan, kemahiran dan mengamalkan nilai berdasarkan objektif pelajaran.
A8: STANDARD KUALITI
A9: Guru membimbing murid secara profesional dan terancang.
A10: TINDAKAN UNTUK MENCAPAI STANDARD
A11: Memberi tunjuk ajar dalam menguasai isi pelajaran dan kemahiran, memandu murid membuat keputusan dan menyelesaikan masalah dan menggunakan sumber pendidikan serta menggabung jalin isi pelajaran dengan kemahiran/mata pelajaran lain mengikut keperluan dan keupayaan murid, dengan betul, tepat, secara berhemah dan bersungguh-sungguh.
A12: TINDAKAN | D12: PENSKORAN
A13: Guru membimbing murid dengan: | D13: 4 | F13: 3 | G13: 2 | H13: 1 | I13: 0
A14: a) | B14: memberi tunjuk ajar/tunjuk cara/panduan menguasai isi pelajaran/konsep/fakta berkaitan pelajaran | D14: i. | E14: mengikut keperluan/pelbagai aras keupayaan murid | F14: dengan mengambil kira mana-mana tiga (3) perkara | G14: dengan mengambil kira mana-mana dua (2) perkara | H14: dengan mengambil kira mana-mana satu (1) perkara | I14: tidak mengambil kira mana-mana perkara
D15: ii. | E15: dengan betul dan tepat
D16: iii. | E16: secara berhemah
D17: iv. | E17: bersungguh-sungguh
A18: SKOR SEKOLAH | J18: =IF((D18+F18+G18+H18+I18)>1,"X",IF((D18+F18+G18+H18+I18)=0,0,"")) -> 0
A19: b) | B19: memberi tunjuk ajar/tunjuk cara/panduan menguasai kemahiran dalam aktiviti pembelajaran | D19: i. | E19: mengikut keperluan/pelbagai aras keupayaan murid | F19: dengan mengambil kira mana-mana tiga (3) perkara | G19: dengan mengambil kira mana-mana dua (2) perkara | H19: dengan mengambil kira mana-mana satu (1) perkara | I19: tidak mengambil kira mana-mana perkara
D20: ii. | E20: dengan betul dan tepat
D21: iii. | E21: secara berhemah
D22: iv. | E22: bersungguh-sungguh
A23: SKOR SEKOLAH | J23: =IF((D23+F23+G23+H23+I23)>1,"X",IF((D23+F23+G23+H23+I23)=0,0,"")) -> 0
A24: c) | B24: memandu murid membuat keputusan dan menyelesaikan masalah dalam aktiviti pembelajaran | D24: i. | E24: mengikut keperluan/pelbagai aras keupayaan murid | F24: dengan mengambil kira mana-mana tiga (3) perkara | G24: dengan mengambil kira mana-mana dua (2) perkara | H24: dengan mengambil kira mana-mana satu (1) perkara | I24: tidak mengambil kira mana-mana perkara
D25: ii. | E25: dengan betul dan tepat
D26: iii. | E26: secara berhemah
D27: iv. | E27: bersungguh-sungguh
A28: SKOR SEKOLAH | J28: =IF((D28+F28+G28+H28+I28)>1,"X",IF((D28+F28+G28+H28+I28)=0,0,"")) -> 0
A29: d) | B29: memandu murid menggunakan/memanfaatkan sumber pendidikan berkaitan pelajaran | D29: i. | E29: mengikut keperluan/pelbagai aras keupayaan murid | F29: dengan mengambil kira mana-mana tiga (3) perkara | G29: dengan mengambil kira mana-mana dua (2) perkara | H29: dengan mengambil kira mana-mana satu (1) perkara | I29: tidak mengambil kira mana-mana perkara
D30: ii. | E30: dengan betul dan tepat
D31: iii. | E31: secara berhemah
D32: iv. | E32: bersungguh-sungguh
A33: SKOR SEKOLAH | J33: =IF((D33+F33+G33+H33+I33)>1,"X",IF((D33+F33+G33+H33+I33)=0,0,"")) -> 0
A34: e) | B34: menggabung/merentas/mengaitkan isi pelajaran dengan tajuk/unit/tema/nilai/kemahiran/mata pelajaran lain dalam aktiviti pembelajaran | D34: i. | E34: mengikut keperluan/pelbagai aras keupayaan murid | F34: dengan mengambil kira mana-mana tiga (3) perkara | G34: dengan mengambil kira mana-mana dua (2) perkara | H34: dengan mengambil kira mana-mana satu (1) perkara | I34: tidak mengambil kira mana-mana perkara
D35: ii. | E35: dengan betul dan tepat
D36: iii. | E36: secara berhemah
D37: iv. | E37: bersungguh-sungguh
A38: SKOR SEKOLAH | J38: =IF((D38+F38+G38+H38+I38)>1,"X",IF((D38+F38+G38+H38+I38)=0,0,"")) -> 0
A39: Jumlah Frekuensi Aspek 4.3.1 | D39: =IF(SUM(D18+D23+D28+D33+D38)="","",(SUM(D18+D23+D28+D33+D38))) -> 0 | F39: =IF(SUM(F18+F23++F28+F33+F38)="","",(SUM(F18+F23++F28+F33+F38))) -> 0 | G39: =IF(SUM(G18+G23++G28+G33+G38)="","",(SUM(G18+G23++G28+G33+G38))) -> 0 | H39: =IF(SUM(H18+H23+H28+H33+H38)="","",(SUM(H18+H23+H28+H33+H38))) -> 0 | I39: =IF(SUM(I18+I23+I28+I33+I38)="","",(SUM(I18+I23+I28+I33+I38))) -> 0
A40: Skor | D40: =IF((D39)="","",(D39)*D13) -> 0 | F40: =IF((F39)="","",(F39)*F13) -> 0 | G40: =IF((G39)="","",(G39)*G13) -> 0 | H40: =IF((H39)="","",(H39)*H13) -> 0 | I40: =IF((I39)="","",(I39)*I20) -> 0
A41: Jumlah Skor Aspek 4.3.1 | D41: =IF(J41="X","X",SUM(D40:I40)) -> 0 | J41: =IF(OR(J38="X",J33="X",J28="X",J23="X",J18="X"),"X",1) -> 1

Sheet 4.4.1
B2: ARAHAN : | C2: Taipkan skor 1 pada baris SKOR SEKOLAH di mana-mana satu skala penskoran sahaja.
A4: ASPEK 4.4 : GURU SEBAGAI PENDORONG
A5: 4.4.1
A6: KRITERIA KRITIKAL
A7: Guru bertindak sebagai pendorong untuk meningkatkan motivasi dan kemahiran insaniah (soft skills) murid.
A8: STANDARD KUALITI
A9: Guru mendorong minda murid dalam melaksanakan aktiviti pembelajaran secara profesional dan terancang.
A10: TINDAKAN UNTUK MENCAPAI STANDARD
A11: Merangsang murid berkomunikasi dan berkolaboratif, mengemukakan soalan yang menjurus ke arah pemikiran kritis dan kreatif dan membuat keputusan atau menyelesaikan masalah, mewujudkan peluang untuk murid memimpin dan mengemukakan soalan berkaitan isi pelajaran serta memperoleh pengetahuan dan kemahiran secara kendiri berdasarkan objektif pelajaran, mengikut keupayaan murid dan dari semasa ke semasa.
A12: TINDAKAN | D12: PENSKORAN
A13: Guru mendorong minda murid dalam melaksanakan aktiviti pembelajaran dengan: | D13: 4 | F13: 3 | G13: 2 | H13: 1 | I13: 0
A14: a) | B14: merangsang murid berkomunikasi | D14: i. | E14: berdasarkan objektif pelajaran | F14: dengan mengambil kira perkara (i) dan (ii) atau perkara (i) dan (iii) | G14: dengan mengambil kira perkara (ii) dan (iii) | H14: dengan mengambil kira mana-mana satu (1) perkara | I14: tidak mengambil kira mana-mana perkara
D15: ii. | E15: mengikut pelbagai aras keupayaan murid
D16: iii. | E16: dari semasa ke semasa
A17: SKOR SEKOLAH | J17: =IF((D17+F17+G17+H17+I17)>1,"X",IF((D17+F17+G17+H17+I17)=0,0,"")) -> 0
A18: b) | B18: merangsang murid berkolaboratif dalam aktiviti pembelajaran | D18: i. | E18: berdasarkan objektif pelajaran | F18: dengan mengambil kira perkara (i) dan (ii) atau perkara (i) dan (iii) | G18: dengan mengambil kira perkara (ii) dan (iii) | H18: dengan mengambil kira mana-mana satu (1) perkara | I18: tidak mengambil kira mana-mana perkara
D19: ii. | E19: mengikut pelbagai aras keupayaan murid
D20: iii. | E20: dari semasa ke semasa
A21: SKOR SEKOLAH | J21: =IF((D21+F21+G21+H21+I21)>1,"X",IF((D21+F21+G21+H21+I21)=0,0,"")) -> 0
A22: c) | B22: mengemukakan soalan yang menjurus ke arah pemikiran kritis dan kreatif | D22: i. | E22: berdasarkan objektif pelajaran | F22: dengan mengambil kira perkara (i) dan (ii) atau perkara (i) dan (iii) | G22: dengan mengambil kira perkara (ii) dan (iii) | H22: dengan mengambil kira mana-mana satu (1) perkara | I22: tidak mengambil kira mana-mana perkara
D23: ii. | E23: mengikut pelbagai aras keupayaan murid
D24: iii. | E24: dari semasa ke semasa
A25: SKOR SEKOLAH | J25: =IF((D25+F25+G25+H25+I25)>1,"X",IF((D25+F25+G25+H25+I25)=0,0,"")) -> 0
A26: d) | B26: mengajukan soalan/mewujudkan situasi yang menjurus ke arah membuat keputusan dan menyelesaikan masalah | D26: i. | E26: berdasarkan objektif pelajaran | F26: dengan mengambil kira perkara (i) dan (ii) atau perkara (i) dan (iii) | G26: dengan mengambil kira perkara (ii) dan (iii) | H26: dengan mengambil kira mana-mana satu (1) perkara | I26: tidak mengambil kira mana-mana perkara
D27: ii. | E27: mengikut pelbagai aras keupayaan murid
D28: iii. | E28: dari semasa ke semasa
A29: SKOR SEKOLAH | J29: =IF((D29+F29+G29+H29+I29)>1,"X",IF((D29+F29+G29+H29+I29)=0,0,"")) -> 0
A30: e) | B30: mewujudkan peluang untuk murid memimpin | D30: i. | E30: berdasarkan objektif pelajaran | F30: dengan mengambil kira perkara (i) dan (ii) atau perkara (i) dan (iii) | G30: dengan mengambil kira perkara (ii) dan (iii) | H30: dengan mengambil kira mana-mana satu (1) perkara | I30: tidak mengambil kira mana-mana perkara
D31: ii. | E31: mengikut pelbagai aras keupayaan murid
D32: iii. | E32: secara berterusan
A33: SKOR SEKOLAH | J33: =IF((D33+F33+G33+H33+I33)>1,"X",IF((D33+F33+G33+H33+I33)=0,0,"")) -> 0
A34: f) | B34: menggalakkan murid mengemukakan soalan berkaitan isi pelajaran | D34: i. | E34: berdasarkan objektif pelajaran | F34: dengan mengambil kira perkara (i) dan (ii) atau perkara (i) dan (iii) | G34: dengan mengambil kira perkara (ii) dan (iii) | H34: dengan mengambil kira mana-mana satu (1) perkara | I34: tidak mengambil kira mana-mana perkara
D35: ii. | E35: mengikut pelbagai aras keupayaan murid
D36: iii. | E36: secara berterusan
A37: SKOR SEKOLAH | J37: =IF((D37+F37+G37+H37+I37)>1,"X",IF((D37+F37+G37+H37+I37)=0,0,"")) -> 0
A38: g) | B38: menggalakkan murid memperoleh pengetahuan dan kemahiran secara kendiri | D38: i. | E38: berdasarkan objektif pelajaran | F38: dengan mengambil kira perkara (i) dan (ii) atau perkara (i) dan (iii) | G38: dengan mengambil kira perkara (ii) dan (iii) | H38: dengan mengambil kira mana-mana satu (1) perkara | I38: tidak mengambil kira mana-mana perkara
D39: ii. | E39: mengikut pelbagai aras keupayaan murid
D40: iii. | E40: secara berterusan
A41: SKOR SEKOLAH | J41: =IF((D41+F41+G41+H41+I41)>1,"X",IF((D41+F41+G41+H41+I41)=0,0,"")) -> 0
A42: Jumlah Frekuensi Aspek 4.4.1 | D42: =IF(SUM(D17+D21+D25+D29+D33+D37+D41)="","",(SUM(D17+D21+D25+D29+D33+D37+D41))) -> 0 | F42: =IF(SUM(F17+F21++F25+F29+F33+F37+F41)="","",(SUM(F17+F21++F25+F29+F33+F37+F41))) -> 0 | G42: =IF(SUM(G17+G21+G25+G29+G33+G37+G41)="","",(SUM(G17+G21+G25+G29+G33+G37+G41))) -> 0 | H42: =IF(SUM(H17+H21+H25+H29+H33+H37+H41)="","",(SUM(H17+H21+H25+H29+H33+H37+H41))) -> 0 | I42: =IF(SUM(I17+I21+I25+I29+I33+I37+I41)="","",(SUM(I17+I21+I25+I29+I33+I37+I41))) -> 0
...

Sheet 4.4.2
B2: ARAHAN : | C2: Taipkan skor 1 pada baris SKOR SEKOLAH di mana-mana satu skala penskoran sahaja.
A4: ASPEK 4.4 : GURU SEBAGAI PENDORONG
A5: 4.4.2
A6: KRITERIA KRITIKAL
A7: Guru bertindak sebagai pendorong untuk meningkatkan motivasi dan kemahiran insaniah (soft skills) murid.
A8: STANDARD KUALITI
A9: Guru mendorong emosi murid dalam melaksanakan aktiviti pembelajaran secara profesional dan terancang.
A10: TINDAKAN UNTUK MENCAPAI STANDARD
A11: Memberi pujian, galakan, penghargaan dan keyakinan serta prihatin terhadap keperluan murid secara berhemah, menyeluruh dan dari semasa ke semasa.
A12: TINDAKAN | D12: PENSKORAN
A13: Guru mendorong emosi murid dalam melaksanakan aktiviti pembelajaran dengan: | D13: 4 | F13: 3 | G13: 2 | H13: 1 | I13: 0
A14: a) | B14: memberi pujian/galakan terhadap perlakuan positif | D14: i. | E14: secara berhemah | F14: dengan mengambil kira perkara (i) dan (ii) atau perkara (i) dan (iii) | G14: dengan mengambil kira perkara (ii) dan (iii) | H14: dengan mengambil kira mana-mana satu (1) perkara | I14: tidak mengambil kira mana-mana perkara
D15: ii. | E15: secara menyeluruh meliputi semua murid
D16: iii. | E16: dari semasa ke semasa
A17: SKOR SEKOLAH | J17: =IF((D17+F17+G17+H17+I17)>1,"X",IF((D17+F17+G17+H17+I17)=0,0,"")) -> 0
A18: b) | B18: memberi penghargaan terhadap hasil kerja/idea yang bernas | D18: i. | E18: secara berhemah | F18: dengan mengambil kira perkara (i) dan (ii) atau perkara (i) dan (iii) | G18: dengan mengambil kira perkara (ii) dan (iii) | H18: dengan mengambil kira mana-mana satu (1) perkara | I18: tidak mengambil kira mana-mana perkara
D19: ii. | E19: secara menyeluruh meliputi semua murid
D20: iii. | E20: dari semasa ke semasa
A21: SKOR SEKOLAH | J21: =IF((D21+F21+G21+H21+I21)>1,"X",IF((D21+F21+G21+H21+I21)=0,0,"")) -> 0
A22: c) | B22: memberi keyakinan dalam mengemukakan soalan/memberi respons | D22: i. | E22: mengikut kesesuaian | F22: dengan mengambil kira perkara (i) dan (ii) atau perkara (i) dan (iii) | G22: dengan mengambil kira perkara (ii) dan (iii) | H22: dengan mengambil kira mana-mana satu (1) perkara | I22: tidak mengambil kira mana-mana perkara
D23: ii. | E23: secara menyeluruh meliputi semua murid
D24: iii. | E24: dari semasa ke semasa
A25: SKOR SEKOLAH | J25: =IF((D25+F25+G25+H25+I25)>1,"X",IF((D25+F25+G25+H25+I25)=0,0,"")) -> 0
A26: d) | B26: prihatin terhadap keperluan murid | D26: i. | E26: secara berhemah | F26: dengan mengambil kira perkara (i) dan (ii) atau perkara (i) dan (iii) | G26: dengan mengambil kira perkara (ii) dan (iii) | H26: dengan mengambil kira mana-mana satu (1) perkara | I26: tidak mengambil kira mana-mana perkara
D27: ii. | E27: secara menyeluruh meliputi semua murid
D28: iii. | E28: dari semasa ke semasa
A29: SKOR SEKOLAH | J29: =IF((D29+F29+G29+H29+I29)>1,"X",IF((D29+F29+G29+H29+I29)=0,0,"")) -> 0
A30: Jumlah Frekuensi Aspek 4.4.2 | D30: =IF(SUM(D17+D21+D25+D29)="","",(SUM(D17+D21+D25+D29))) -> 0 | F30: =IF(SUM(F17+F21+F25+F29)="","",(SUM(F17+F21+F25+F29))) -> 0 | G30: =IF(SUM(G17+G21+G25+G29)="","",(SUM(G17+G21+G25+G29))) -> 0 | H30: =IF(SUM(H17+H21+H25+H29)="","",(SUM(H17+H21+H25+H29))) -> 0 | I30: =IF(SUM(I17+I21+I25+I29)="","",(SUM(I17+I21+I25+I29))) -> 0
A31: Skor | D31: =IF((D30)="","",(D30)*D13) -> 0 | F31: =IF((F30)="","",(F30)*F13) -> 0 | G31: =IF((G30)="","",(G30)*G13) -> 0 | H31: =IF((H30)="","",(H30)*H13) -> 0 | I31: =IF((I30)="","",(I30)*I13) -> 0
A32: Jumlah Skor Aspek 4.4.2 | D32: =IF(J32="X","X",SUM(D31:I31)) -> 0 | J32: =IF(OR(J29="X",J25="X",J21="X",J17="X"),"X",1) -> 1

Sheet 4.5.1
B2: ARAHAN : | C2: Taipkan skor 1 pada baris SKOR SEKOLAH di mana-mana satu skala penskoran sahaja.
A4: ASPEK 4.5 : GURU SEBAGAI PENILAI
A5: 4.5.1
A6: KRITERIA KRITIKAL
A7: Guru bertindak sebagai penilai untuk mengesan tahap penguasaan murid.
A8: STANDARD KUALITI
A9: Guru melaksanakan penilaian secara sistematik dan terancang.
A10: TINDAKAN UNTUK MENCAPAI STANDARD
A11: Menggunakan pelbagai kaedah pentaksiran, menjalankan aktiviti pemulihan/pengayaan, memberi tugasan, membuat refleksi serta menyemak hasil kerja murid berdasarkan objektif pelajaran, mengikut arahan pelaksanaan pentaksiran yang berkuat kuasa dan ketetapan, secara menyeluruh dan dari semasa ke semasa.
A12: TINDAKAN | D12: PENSKORAN
A13: Guru melaksanakan penilaian dengan: | D13: 4 | F13: 3 | G13: 2 | H13: 1 | I13: 0
A14: a) | B14: menggunakan pelbagai kaedah pentaksiran dalam PdPc | D14: i. | E14: berdasarkan objektif pelajaran | F14: dengan mengambil kira mana-mana tiga (3) perkara | G14: dengan mengambil kira mana-mana dua (2) perkara | H14: dengan mengambil kira mana-mana satu (1) perkara | I14: tidak mengambil kira mana-mana perkara
D15: ii. | E15: mengikut arahan pelaksanaan pentaksiran yang berkuat kuasa /ketetapan kurikulum
D16: iii. | E16: secara menyeluruh kepada semua murid
D17: iv. | E17: dari semasa ke semasa
A18: SKOR SEKOLAH | J18: =IF((D18+F18+G18+H18+I18)>1,"X",IF((D18+F18+G18+H18+I18)=0,0,"")) -> 0
A19: b) | B19: menjalankan aktiviti pemulihan/pengayaan dalam PdPc | D19: i. | E19: berdasarkan objektif pelajaran | F19: dengan mengambil kira mana-mana tiga (3) perkara | G19: dengan mengambil kira mana-mana dua (2) perkara | H19: dengan mengambil kira mana-mana satu (1) perkara | I19: tidak mengambil kira mana-mana perkara
D20: ii. | E20: mengikut ketetapan kurikulum
D21: iii. | E21: secara menyeluruh kepada semua murid
D22: iv. | E22: dari semasa ke semasa
A23: SKOR SEKOLAH | J23: =IF((D23+F23+G23+H23+I23)>1,"X",IF((D23+F23+G23+H23+I23)=0,0,"")) -> 0
A24: c) | B24: memberi latihan/tugasan berkaitan pelajaran | D24: i. | E24: berdasarkan objektif pelajaran | F24: dengan mengambil kira mana-mana tiga (3) perkara | G24: dengan mengambil kira mana-mana dua (2) perkara | H24: dengan mengambil kira mana-mana satu (1) perkara | I24: tidak mengambil kira mana-mana perkara
D25: ii. | E25: mengikut ketetapan kurikulum
D26: iii. | E26: secara menyeluruh dari segi kecukupan dan kecakupan
D27: iv. | E27: dari semasa ke semasa
A28: SKOR SEKOLAH | J28: =IF((D28+F28+G28+H28+I28)>1,"X",IF((D28+F28+G28+H28+I28)=0,0,"")) -> 0
A29: d) | B29: membuat refleksi PdPc | D29: i. | E29: berdasarkan objektif pelajaran | F29: dengan mengambil kira mana-mana tiga (3) perkara | G29: dengan mengambil kira mana-mana dua (2) perkara | H29: dengan mengambil kira mana-mana satu (1) perkara | I29: tidak mengambil kira mana-mana perkara
D30: ii. | E30: mengikut arahan pelaksanaan pentaksiran yang berkuat kuasa /ketetapan kurikulum
D31: iii. | E31: secara menyeluruh kepada semua murid
D32: iv. | E32: dari semasa ke semasa
A33: SKOR SEKOLAH | J33: =IF((D33+F33+G33+H33+I33)>1,"X",IF((D33+F33+G33+H33+I33)=0,0,"")) -> 0
A34: e) | B34: menyemak/menilai hasil kerja/gerak kerja/latihan/tugasan | D34: i. | E34: berdasarkan objektif pelajaran | F34: dengan mengambil kira mana-mana tiga (3) perkara | G34: dengan mengambil kira mana-mana dua (2) perkara | H34: dengan mengambil kira mana-mana satu (1) perkara | I34: tidak mengambil kira mana-mana perkara
D35: ii. | E35: mengikut ketetapan kurikulum
D36: iii. | E36: secara menyeluruh kepada semua murid
D37: iv. | E37: dari semasa ke semasa
A38: SKOR SEKOLAH | J38: =IF((D38+F38+G38+H38+I38)>1,"X",IF((D38+F38+G38+H38+I38)=0,0,"")) -> 0
A39: Jumlah Frekuensi Aspek 4.5.1 | D39: =IF(SUM(D18+D23+D28+D33+D38)="","",(SUM(D18+D23+D28+D33+D38))) -> 0 | F39: =IF(SUM(F18+F23++F28+F33+F38)="","",(SUM(F18+F23++F28+F33+F38))) -> 0 | G39: =IF(SUM(G18+G23++G28+G33+G38)="","",(SUM(G18+G23++G28+G33+G38))) -> 0 | H39: =IF(SUM(H18+H23+H28+H33+H38)="","",(SUM(H18+H23+H28+H33+H38))) -> 0 | I39: =IF(SUM(I18+I23+I28+I33+I38)="","",(SUM(I18+I23+I28+I33+I38))) -> 0
A40: Skor | D40: =IF((D39)="","",(D39)*D13) -> 0 | F40: =IF((F39)="","",(F39)*F13) -> 0 | G40: =IF((G39)="","",(G39)*G13) -> 0 | H40: =IF((H39)="","",(H39)*H13) -> 0 | I40: =IF((I39)="","",(I39)*I21) -> 0
A41: Jumlah Skor Aspek 4.5.1 | J41: =IF(OR(J38="X",J33="X",J28="X",J23="X",J18="X"),"X",1) -> 1

Sheet 4.6.1
B2: ARAHAN : | C2: Taipkan skor 1 pada baris SKOR SEKOLAH di mana-mana satu skala penskoran sahaja.
A4: ASPEK 4.6 : MURID SEBAGAI PEMBELAJAR AKTIF
A5: 4.6.1
A6: KRITERIA KRITIKAL
A7: Murid bertindak sebagai pembelajar aktif untuk menguasai pengetahuan dan kemahiran serta mengamalkan nilai positif. .
A8: STANDARD KUALITI
A9: Murid melibatkan diri dalam proses pembelajaran secara berkesan.
A10: TINDAKAN UNTUK MENCAPAI STANDARD
A11: Memberi respons, berkomunikasi dan melaksanakan aktiviti secara kolaboratif, berpemikiran kritis dan kreatif, mengemukakan soalan, menyesaikan masalah dan mengaitkan isi pelajaran dengan kehidupan berdasarkan objektif pelajaran secara aktif, yakin dan berhemah.
A12: TINDAKAN | D12: PENSKORAN
A13: Murid melibatkan diri dalam proses pembelajaran dengan: | D13: 4 | F13: 3 | H13: 2 | J13: 1 | L13: 0
A14: a) | B14: memberi respons berkaitan isi pelajaran | D14: i. | E14: dengan pelibatan 90% hingga 100% murid | F14: i. | G14: dengan pelibatan 80% hingga 89% murid | H14: i. | I14: dengan pelibatan 50% hingga 79% murid | J14: i. | K14: dengan pelibatan 1% hingga 49% murid | L14: tidak memenuhi mana-mana perkara
D15: ii. | E15: selaras dengan objektif pelajaran | F15: ii. | G15: dengan memenuhi sekurang-kurangnya dua (2) daripada perkara (ii), (iii) atau (iv) | H15: ii. | I15: dengan memenuhi sekurang-kurangnya satu (1) daripada perkara (ii), (iii) atau (iv) | J15: ii. | K15: dengan memenuhi sekurang-kurangnya satu (1) daripada perkara (ii), (iii) atau (iv)
D16: iii. | E16: dengan yakin
D17: iv. | E17: secara berhemah/saling menghormati/bersungguh-sungguh
A18: SKOR SEKOLAH | M18: =IF((D18+F18+H18+J18+L18)>1,"X",IF((D18+F18+H18+J18+L18)=0,0,"")) -> 0
A19: b) | B19: berkomunikasi dalam melaksanakan aktiviti pembelajaran | D19: i. | E19: dengan pelibatan 90% hingga 100% murid | F19: i. | G19: dengan pelibatan 80% hingga 89% murid | H19: i. | I19: dengan pelibatan 50% hingga 79% murid | J19: i. | K19: dengan pelibatan 1% hingga 49% murid | L19: tidak memenuhi mana-mana perkara
D20: ii. | E20: selaras dengan objektif pelajaran | F20: ii. | G20: dengan memenuhi sekurang-kurangnya dua (2) daripada perkara (ii), (iii) atau (iv) | H20: ii. | I20: dengan memenuhi sekurang-kurangnya satu (1) daripada perkara (ii), (iii) atau (iv) | J20: ii. | K20: dengan memenuhi sekurang-kurangnya satu (1) daripada perkara (ii), (iii) atau (iv)
D21: iii. | E21: dengan yakin
D22: iv. | E22: secara berhemah/saling menghormati/bersungguh-sungguh
A23: SKOR SEKOLAH | M23: =IF((D23+F23+H23+J23+L23)>1,"X",IF((D23+F23+H23+J23+L23)=0,0,"")) -> 0
A24: c) | B24: melaksanakan aktiviti pembelajaran secara kolaboratif | D24: i. | E24: dengan pelibatan 90% hingga 100% murid | F24: i. | G24: dengan pelibatan 80% hingga 89% murid | H24: i. | I24: dengan pelibatan 50% hingga 79% murid | J24: i. | K24: dengan pelibatan 1% hingga 49% murid | L24: tidak memenuhi mana-mana perkara
D25: ii. | E25: selaras dengan objektif pelajaran | F25: ii. | G25: dengan memenuhi sekurang-kurangnya dua (2) daripada perkara (ii), (iii) atau (iv) | H25: ii. | I25: dengan memenuhi sekurang-kurangnya satu (1) daripada perkara (ii), (iii) atau (iv) | J25: ii. | K25: dengan memenuhi sekurang-kurangnya satu (1) daripada perkara (ii), (iii) atau (iv)
D26: iii. | E26: dengan yakin
D27: iv. | E27: secara berhemah/saling menghormati/bersungguh-sungguh
A28: SKOR SEKOLAH | F28: 1 | M28: =IF((D28+F28+H28+J28+L28)>1,"X",IF((D28+F28+H28+J28+L28)=0,0,""))
A29: d) | B29: memberi respons yang menjurus ke arah pemikiran kritis dan kreatif berkaitan isi pelajaran | D29: i. | E29: dengan pelibatan 50% hingga 100% murid | F29: i. | G29: dengan pelibatan 25% hingga 49% murid | H29: i. | I29: dengan pelibatan 10% hingga 24% murid | J29: i. | K29: dengan pelibatan kurang daripada 10% murid | L29: tidak memenuhi mana-mana perkara
D30: ii. | E30: selaras dengan objektif pelajaran | F30: ii. | G30: dengan memenuhi sekurang-kurangnya dua (2) daripada perkara (ii), (iii) atau (iv) | H30: ii. | I30: denganmemenuhi sekurang-kurangnya satu (1) daripada perkara (ii), (iii) atau (iv) | J30: ii. | K30: denga memenuhi sekurang-kurangnya satu (1) daripada perkara (ii), (iii) atau (iv)
D31: iii. | E31: dengan yakin
D32: iv. | E32: secara berhemah/saling menghormati/bersungguh-sungguh
A33: SKOR SEKOLAH | M33: =IF((D33+F33+H33+J33+L33)>1,"X",IF((D33+F33+H33+J33+L33)=0,0,"")) -> 0
A34: e) | B34: mengemukakan soalan berkaitan isi pelajaran | D34: i. | E34: dengan pelibatan 50% hingga 100% murid | F34: i. | G34: dengan pelibatan 25% hingga 49% murid | H34: i. | I34: dengan pelibatan 10% hingga 24% murid | J34: i. | K34: dengan pelibatan kurang daripada 10% murid | L34: tidak memenuhi mana-mana perkara
D35: ii. | E35: selaras dengan objektif pelajaran | F35: ii. | G35: dengan memenuhi sekurang-kurangnya dua (2) daripada perkara (ii), (iii) atau (iv) | H35: ii. | I35: denganmemenuhi sekurang-kurangnya satu (1) daripada perkara (ii), (iii) atau (iv) | J35: ii. | K35: denga memenuhi sekurang-kurangnya satu (1) daripada perkara (ii), (iii) atau (iv)
D36: iii. | E36: dengan yakin
D37: iv. | E37: secara berhemah/saling menghormati/bersungguh-sungguh
A38: SKOR SEKOLAH | H38: 1 | M38: =IF((D38+F38+H38+J38+L38)>1,"X",IF((D38+F38+H38+J38+L38)=0,0,""))
A39: f) | B39: mengaitkan isi pelajaran dengan kehidupan murid/isu lokal/global | D39: i. | E39: dengan pelibatan 50% hingga 100% murid | F39: i. | G39: dengan pelibatan 25% hingga 49% murid | H39: i. | I39: dengan pelibatan 10% hingga 24% murid | J39: i. | K39: dengan pelibatan kurang daripada 10% murid | L39: tidak memenuhi mana-mana perkara
D40: ii. | E40: selaras dengan objektif pelajaran | F40: ii. | G40: dengan memenuhi sekurang-kurangnya dua (2) daripada perkara (ii), (iii) atau (iv) | H40: ii. | I40: denganmemenuhi sekurang-kurangnya satu (1) daripada perkara (ii), (iii) atau (iv) | J40: ii. | K40: denga memenuhi sekurang-kurangnya satu (1) daripada perkara (ii), (iii) atau (iv)
D41: iii. | E41: dengan yakin
D42: iv. | E42: secara berhemah/saling menghormati/bersungguh-sungguh
...

Sheet Rumusan
C2: Nama Guru | D2: No. KP | E2: Jenis Penilaian | F2: Tarikh | G2: Mata pelajaran | H2: Kelas | I2: 4.1.1 | J2: 4.2.1 | K2: 4.2.2 | L2: 4.3.1 | M2: 4.4.1 | N2: 4.4.2 | O2: 4.5.1 | P2: 4.6.1 | Q2: Jumlah skor
C3: ='4.1.1'!C4 -> 0 | D3: ='4.1.1'!C5 -> 0 | E3: ='4.1.1'!C6 -> 0 | F3: ='4.1.1'!C7 -> 0 | G3: ='4.1.1'!C8 -> 0 | H3: ='4.1.1'!C9 -> 0 | I3: =IFERROR('4.1.1'!D39/12*100*0.1,"X") -> 0 | J3: =IFERROR('4.2.1'!D28/12*100*0.1,"X") -> 0 | K3: =IFERROR('4.2.2'!D32/16*100*0.05,"X") -> 4.375 | L3: =IFERROR('4.3.1'!D41/20*100*0.15,"X") -> 0 | M3: =IFERROR('4.4.1'!D44/28*100*0.25,"X") -> 0 | N3: =IFERROR('4.4.2'!D32/16*100*0.05,"X") -> 0 | O3: =IFERROR('4.5.1'!D41/20*100*0.1,"X") -> 0 | P3: =IFERROR('4.6.1'!D51/28*100*0.2,"X") -> 3.5714286 | Q3: =SUM(I3:P3) -> 7.9464286
D5: JUMLAH SKOR : 85.47
D7: ULASAN DAN CADANGAN PENAMBAHBAIKAN
D16: Nama Pemantau :
D17: Jawatan :
